<?xml version="1.0" ?>
<!-- =================================================================================== -->
<!-- |    This document was autogenerated by xacro from xacro/robot.xacro              | -->
<!-- |    EDITING THIS FILE BY HAND IS NOT RECOMMENDED                                 | -->
<!-- =================================================================================== -->
<robot name="hector_description">
  <material name="black">
    <color rgba="0.0 0.0 0.0 1.0"/>
  </material>
  <material name="blue">
    <color rgba="0.0 0.0 0.8 1.0"/>
  </material>
  <material name="green">
    <color rgba="0.0 0.8 0.0 1.0"/>
  </material>
  <material name="grey">
    <color rgba="0.2 0.2 0.2 1.0"/>
  </material>
  <material name="silver">
    <color rgba="0.9137254901960784 0.9137254901960784 0.8470588235294118 1.0"/>
  </material>
  <material name="orange">
    <color rgba="1.0 0.4235294117647059 0.0392156862745098 1.0"/>
  </material>
  <material name="brown">
    <color rgba="0.8705882352941177 0.8117647058823529 0.7647058823529411 1.0"/>
  </material>
  <material name="red">
    <color rgba="0.8 0.0 0.0 1.0"/>
  </material>
  <material name="white">
    <color rgba="1.0 1.0 1.0 1.0"/>
  </material>
  <!-- ros_control plugin -->
  <gazebo>
    <plugin filename="libgazebo_ros_control.so" name="gazebo_ros_control">
      <robotNamespace>/hector_gazebo</robotNamespace>
      <robotSimType>gazebo_ros_control/DefaultRobotHWSim</robotSimType>
    </plugin>
  </gazebo>
  <!-- Show the trajectory of trunk center. -->
  <gazebo>
    <plugin filename="libLinkPlot3DPlugin.so" name="3dplot">
      <frequency>10</frequency>
      <plot>
        <link>base</link>
        <pose>0 0 0 0 0 0</pose>
        <material>Gazebo/Yellow</material>
      </plot>
    </plugin>
  </gazebo>
  <gazebo>
    <plugin filename="libgazebo_ros_force.so" name="gazebo_ros_force">
      <bodyName>trunk</bodyName>
      <topicName>/apply_force/trunk</topicName>
    </plugin>
  </gazebo>
  <gazebo reference="imu_link">
    <gravity>true</gravity>
    <sensor name="imu_sensor" type="imu">
      <always_on>true</always_on>
      <update_rate>1000</update_rate>
      <visualize>true</visualize>
      <topic>__default_topic__</topic>
      <plugin filename="libgazebo_ros_imu_sensor.so" name="imu_plugin">
        <topicName>trunk_imu</topicName>
        <bodyName>imu_link</bodyName>
        <updateRateHZ>1000.0</updateRateHZ>
        <gaussianNoise>0.00</gaussianNoise>
        <xyzOffset>0 0 0</xyzOffset>
        <rpyOffset>0 0 0</rpyOffset>
        <frameName>imu_link</frameName>
      </plugin>
      <pose>0 0 0 0 0 0</pose>
    </sensor>
  </gazebo>
  <gazebo reference="base">
    <material>Gazebo/Green</material>
    <turnGravityOff>false</turnGravityOff>
  </gazebo>
  <gazebo reference="trunk">
    <mu1>0.2</mu1>
    <mu2>0.2</mu2>
    <material>Gazebo/DarkGrey</material>
  </gazebo>
  <gazebo reference="trunkcol">
    <mu1>0.2</mu1>
    <mu2>0.2</mu2>
  </gazebo>
  <gazebo reference="stick_link">
    <mu1>0.2</mu1>
    <mu2>0.2</mu2>
    <material>Gazebo/White</material>
  </gazebo>
  <gazebo reference="imu_link">
    <mu1>1</mu1>
    <mu2>1</mu2>
    <material>Gazebo/Red</material>
  </gazebo>
  <!-- L leg -->
  <gazebo reference="L_hip">
    <mu1>1</mu1>
    <mu2>1</mu2>
    <kp value="100000.0"/>
    <kd value="1000.0"/>
    <material>Gazebo/Grey</material>
  </gazebo>
  <gazebo reference="L_hip2">
    <mu1>1</mu1>
    <mu2>1</mu2>
    <kp value="100000.0"/>
    <kd value="1000.0"/>
    <material>Gazebo/Grey</material>
  </gazebo>
  <gazebo reference="L_thigh">
    <mu1>1</mu1>
    <mu2>1</mu2>
    <kp value="100000.0"/>
    <kd value="1000.0"/>
    <self_collide>0</self_collide>
    <material>Gazebo/Grey</material>
  </gazebo>
  <gazebo reference="L_calf">
    <mu1>1</mu1>
    <mu2>1</mu2>
    <kp value="100000.0"/>
    <kd value="1000.0"/>
    <self_collide>0</self_collide>
    <material>Gazebo/Grey</material>
  </gazebo>
  <gazebo reference="L_toe">
    <mu1>3</mu1>
    <mu2>3</mu2>
    <kp value="1000000.0"/>
    <kd value="1000.0"/>
    <self_collide>0</self_collide>
    <material>Gazebo/Grey</material>
  </gazebo>
  <!--R leg -->
  <gazebo reference="R_hip">
    <mu1>1</mu1>
    <mu2>1</mu2>
    <kp value="100000.0"/>
    <kd value="1000.0"/>
    <material>Gazebo/Grey</material>
  </gazebo>
  <gazebo reference="R_hip2">
    <mu1>1</mu1>
    <mu2>1</mu2>
    <kp value="100000.0"/>
    <kd value="1000.0"/>
    <material>Gazebo/Grey</material>
  </gazebo>
  <gazebo reference="R_thigh">
    <mu1>1</mu1>
    <mu2>1</mu2>
    <kp value="100000.0"/>
    <kd value="1000.0"/>
    <self_collide>0</self_collide>
    <material>Gazebo/Grey</material>
  </gazebo>
  <gazebo reference="R_calf">
    <mu1>1</mu1>
    <mu2>1</mu2>
    <kp value="100000.0"/>
    <kd value="1000.0"/>
    <self_collide>0</self_collide>
    <material>Gazebo/Grey</material>
  </gazebo>
  <gazebo reference="R_toe">
    <mu1>3</mu1>
    <mu2>3</mu2>
    <kp value="1000000.0"/>
    <kd value="1000.0"/>
    <self_collide>0</self_collide>
    <material>Gazebo/Grey</material>
  </gazebo>
  <!-- <xacro:stairs stairs="15" xpos="0" ypos="0" zpos="0" /> -->
  <link name="base">
    <visual>
      <origin rpy="0 0 0" xyz="0 0 0"/>
      <geometry>
        <box size="0.001 0.001 0.001"/>
      </geometry>
    </visual>
  </link>
  <joint name="floating_base" type="fixed">
    <origin rpy="0 0 0" xyz="0 0 0"/>
    <parent link="base"/>
    <child link="trunk"/>
  </joint>
  <link name="trunk">
    <visual>
      <origin rpy="0 0 0" xyz="0 0 0"/>
      <geometry>
        <mesh filename="package://hector_description/meshes/body.STL" scale="1 1 1"/>
      </geometry>
      <material name="white"/>
    </visual>
    <collision>
      <origin rpy="0 0 0" xyz="0 0 0"/>
      <geometry>
        <box size="0.125 0.19 0.248"/>
      </geometry>
    </collision>
    <inertial>
      <origin rpy="0 0 0" xyz="0.0 0.0 0.0"/>
      <mass value="5.7"/>
      <inertia ixx="0.0463619" ixy="0.0" ixz="0.0" iyy="0.036636" iyz="0.0" izz="0.024569"/>
    </inertial>
  </link>
  <joint name="imu_joint" type="fixed">
    <parent link="trunk"/>
    <child link="imu_link"/>
    <origin rpy="0 0 0" xyz="0 0 0"/>
  </joint>
  <link name="imu_link">
    <inertial>
      <mass value="0.001"/>
      <origin rpy="0 0 0" xyz="0 0 0"/>
      <inertia ixx="0.0001" ixy="0" ixz="0" iyy="0.0001" iyz="0" izz="0.0001"/>
    </inertial>
    <visual>
      <origin rpy="0 0 0" xyz="0 0 0"/>
      <geometry>
        <box size="0.001 0.001 0.001"/>
      </geometry>
      <material name="red"/>
    </visual>
    <collision>
      <origin rpy="0 0 0" xyz="0 0 0"/>
      <geometry>
        <box size=".001 .001 .001"/>
      </geometry>
    </collision>
  </link>
  <!-- TODO: add inertial properties and update controller -->
  <joint name="head" type="fixed">
    <parent link="trunk"/>
    <child link="head_link"/>
    <origin rpy="0 3.141592653589793 1.5707963267948966" xyz="0.07 0.0458 0.315"/>
  </joint>
  <link name="head_link">
    <inertial>
      <mass value="0.001"/>
      <origin rpy="0 0 0" xyz="0 0 0"/>
      <inertia ixx="0.0001" ixy="0" ixz="0" iyy="0.0001" iyz="0" izz="0.0001"/>
    </inertial>
    <visual>
      <origin rpy="0 0 0" xyz="0 0 0"/>
      <geometry>
        <mesh filename="package://hector_description/meshes/Head.STL" scale="0.001 0.001 0.001"/>
      </geometry>
      <material name="red"/>
    </visual>
    <collision>
      <origin rpy="0 0 0" xyz="0 0 0"/>
      <geometry>
        <box size=".001 .001 .001"/>
      </geometry>
    </collision>
  </link>
  <joint name="L_hip_joint" type="revolute">
    <origin rpy="0 0 0" xyz="0.0 0.047 -0.1265"/>
    <parent link="trunk"/>
    <child link="L_hip"/>
    <axis xyz="0 0 1"/>
    <dynamics damping="0.1" friction="0.0"/>
    <limit effort="33.5" lower="-0.5235987755982988" upper="0.5235987755982988" velocity="21"/>
  </joint>
  <link name="L_hip">
    <visual>
      <origin rpy="0 0 0" xyz="0 0 0"/>
      <geometry>
        <mesh filename="package://hector_description/meshes/L_hip1.STL" scale="1 1 1"/>
      </geometry>
      <material name="orange"/>
    </visual>
    <collision>
      <origin rpy="0 0 0" xyz="0.015 0.0 -0.002"/>
      <geometry>
        <box size="0.0001 0.0001 0.0001"/>
      </geometry>
    </collision>
    <inertial>
      <origin rpy="0 0 0" xyz="0.025109 -0.002292 -0.024732"/>
      <mass value="0.224"/>
      <inertia ixx="2.104e-06" ixy="0.0" ixz="0.0" iyy="5.354e-06" iyz="0.0" izz="7.416e-06"/>
    </inertial>
  </link>
  <!--this link is only for motor mass&colllision-->
  <joint name="L_hip_trans_joint" type="fixed">
    <origin rpy="0 0 0" xyz="0.079 0.015 -0.0705"/>
    <parent link="L_hip"/>
    <child link="L_hip_trans"/>
  </joint>
  <link name="L_hip_trans">
    <collision>
      <origin rpy="0 1.5707963267948966 0" xyz="0 0 0"/>
      <geometry>
        <cylinder length="0.04" radius="0.045"/>
      </geometry>
    </collision>
    <inertial>
      <origin rpy="0 0 0" xyz="0 0 0"/>
      <mass value="0.65"/>
      <inertia ixx="0.00043875" ixy="0.0" ixz="0.0" iyy="0.00043875" iyz="0.0" izz="0.000658125"/>
    </inertial>
  </link>
  <joint name="L_hip2_joint" type="revolute">
    <origin rpy="0 0 0" xyz="0.0465 0.015 -0.0705"/>
    <parent link="L_hip"/>
    <child link="L_hip2"/>
    <axis xyz="1 0 0"/>
    <dynamics damping="0.1" friction="0.0"/>
    <limit effort="33.5" lower="-0.5235987755982988" upper="0.5235987755982988" velocity="21"/>
  </joint>
  <link name="L_hip2">
    <visual>
      <origin rpy="0 0 0" xyz="0 0 0"/>
      <geometry>
        <mesh filename="package://hector_description/meshes/L_hip2.STL" scale="1 1 1"/>
      </geometry>
      <material name="red"/>
    </visual>
    <collision>
      <origin rpy="0 0 0" xyz="-0.1 0 0"/>
      <geometry>
        <box size="1e-05 1e-05 1e-05"/>
      </geometry>
    </collision>
    <inertial>
      <origin rpy="0 0 0" xyz="-0.033217 -0.010231 0"/>
      <mass value="0.095"/>
      <inertia ixx="5.1083e-05" ixy="0.0" ixz="0.0" iyy="1.39825e-05" iyz="0.0" izz="9.3473e-05"/>
    </inertial>
  </link>
  <!--this link is only for collision-->
  <joint name="L_hip2_trans_joint" type="fixed">
    <origin rpy="0 0 0" xyz="-0.06 -0.015 0.0"/>
    <parent link="L_hip2"/>
    <child link="L_hip2_trans"/>
  </joint>
  <link name="L_hip2_trans">
    <collision>
      <origin rpy="-1.5707963267948966 0 0" xyz="0 0 0"/>
      <geometry>
        <cylinder length="0.04" radius="0.045"/>
      </geometry>
    </collision>
    <inertial>
      <origin rpy="-1.5707963267948966 0 0" xyz="0 0 0"/>
      <mass value="0.65"/>
      <inertia ixx="0.00043875" ixy="0.0" ixz="0.0" iyy="0.00043875" iyz="0.0" izz="0.000658125"/>
    </inertial>
  </link>
  <joint name="L_thigh_joint" type="revolute">
    <origin rpy="0 0.7853981633974483 0" xyz="-0.06 0.018 0"/>
    <parent link="L_hip2"/>
    <child link="L_thigh"/>
    <axis xyz="0 1 0"/>
    <joint_properties damping="0.1" friction="0.0"/>
    <!-- <limit effort="${thigh_torque_max}" velocity="${thigh_velocity_max}"/> -->
    <limit effort="33.5" lower="-3.14" upper="3.14" velocity="21"/>
  </joint>
  <link name="L_thigh">
    <visual>
      <origin rpy="0 0 0" xyz="0 0 0"/>
      <geometry>
        <mesh filename="package://hector_description/meshes/L_thigh.STL" scale="1 1 1"/>
      </geometry>
      <material name="white"/>
    </visual>
    <collision>
      <origin rpy="0 0 0" xyz="0.0 0.0175 -0.09"/>
      <geometry>
        <box size="0.06 0.035 0.18"/>
      </geometry>
    </collision>
    <inertial>
      <origin rpy="0 0 0" xyz="-0.000147 0.01991 -0.081117"/>
      <mass value="0.642"/>
      <inertia ixx="0.004437615" ixy="0.0" ixz="0.0" iyy="0.004788512" iyz="0.0" izz="0.000661818"/>
    </inertial>
  </link>
  <!--this link is only for collision-->
  <joint name="L_thigh1_trans_joint" type="fixed">
    <origin rpy="0 0 0" xyz="0.0 0.0625 0.0"/>
    <parent link="L_thigh"/>
    <child link="L_thigh1_trans"/>
  </joint>
  <link name="L_thigh1_trans">
    <collision>
      <origin rpy="-1.5707963267948966 0 0" xyz="0 0 0"/>
      <geometry>
        <cylinder length="0.04" radius="0.045"/>
      </geometry>
    </collision>
    <inertial>
      <origin rpy="-1.5707963267948966 0 0" xyz="0 0 0"/>
      <mass value="0.65"/>
      <inertia ixx="0.00043875" ixy="0.0" ixz="0.0" iyy="0.00043875" iyz="0.0" izz="0.000658125"/>
    </inertial>
  </link>
  <!--this link is only for collision-->
  <joint name="L_thigh2_trans_joint" type="fixed">
    <origin rpy="0 0 0" xyz="0.0 -0.0225 -0.097"/>
    <parent link="L_thigh"/>
    <child link="L_thigh2_trans"/>
  </joint>
  <link name="L_thigh2_trans">
    <collision>
      <origin rpy="-1.5707963267948966 0 0" xyz="0 0 0"/>
      <geometry>
        <cylinder length="0.04" radius="0.045"/>
      </geometry>
    </collision>
    <inertial>
      <origin rpy="-1.5707963267948966 0 0" xyz="0 0 0"/>
      <mass value="0.65"/>
      <inertia ixx="0.00043875" ixy="0.0" ixz="0.0" iyy="0.00043875" iyz="0.0" izz="0.000658125"/>
    </inertial>
  </link>
  <joint name="L_calf_joint" type="revolute">
    <origin rpy="0 -1.5707963267948966 0" xyz="0.0 0 -0.22"/>
    <parent link="L_thigh"/>
    <child link="L_calf"/>
    <axis xyz="0 1 0"/>
    <joint_properties damping="0.1" friction="0.0"/>
    <limit effort="33.5" lower="-3.14" upper="3.14" velocity="21"/>
  </joint>
  <link name="L_calf">
    <visual>
      <origin rpy="0 0 0" xyz="0 0 0"/>
      <geometry>
        <mesh filename="package://hector_description/meshes/L_calf.STL" scale="1 1 1"/>
      </geometry>
      <material name="orange"/>
    </visual>
    <collision>
      <origin rpy="0 0 0" xyz="0.0 0.0 -0.11"/>
      <geometry>
        <cylinder length="0.2" radius="0.015"/>
      </geometry>
    </collision>
    <inertial>
      <origin rpy="0 0 0" xyz="0.0 0.020417 -0.1141"/>
      <mass value="0.303"/>
      <inertia ixx="0.001911" ixy="0.0" ixz="0.0" iyy="0.00191038" iyz="0.0" izz="6.8352e-05"/>
    </inertial>
  </link>
  <joint name="L_toe_joint" type="revolute">
    <origin rpy="0 0.7853981633974483 0" xyz="0.0 0.0 -0.22"/>
    <parent link="L_calf"/>
    <child link="L_toe"/>
    <axis xyz="0 1 0"/>
    <joint_properties damping="0.1" friction="0.0"/>
    <limit effort="33.5" lower="-1.4" upper="1.4" velocity="21"/>
  </joint>
  <link name="L_toe">
    <visual>
      <origin rpy="0 0 0" xyz="0 0 0"/>
      <geometry>
        <mesh filename="package://hector_description/meshes/L_foot.STL" scale="1 1 1"/>
      </geometry>
      <material name="red"/>
    </visual>
    <collision>
      <origin rpy="0 0 0" xyz="0.01 0.0194 -0.02"/>
      <geometry>
        <box size="0.15 0.02 0.04"/>
      </geometry>
    </collision>
    <inertial>
      <origin rpy="0 0 0" xyz="0.010569 0.017949 -0.017118"/>
      <mass value="0.214"/>
      <inertia ixx="5.7298e-05" ixy="0.0" ixz="0.0" iyy="0.000290752" iyz="0.0" izz="0.000249491"/>
    </inertial>
  </link>
  <joint name="L_foot_fixed_1" type="revolute">
    <origin rpy="0 0 0" xyz="0.0 -0.0 -0.04"/>
    <parent link="L_toe"/>
    <child link="L_foot_link_1"/>
    <!-- just for the calculate the jacobian -->
    <axis xyz="0 1 0"/>
    <joint_properties damping="0.1" friction="0.0"/>
    <limit effort="33.5" lower="-1.4" upper="1.4" velocity="21"/>
  </joint>
  <link name="L_foot_link_1">
    <visual>
      <origin rpy="0 0 0" xyz="0.0 -0.0 -0.02"/>
      <geometry>
        <sphere radius="0.004"/>
      </geometry>
      <!-- <geometry>
                    <box size="${foot_length} ${foot_width} ${foot_height}"/>
                </geometry>  -->
      <material name="blue"/>
    </visual>
    <collision>
      <origin rpy="0 0 0" xyz="0.0 -0.0 -0.02"/>
      <geometry>
        <sphere radius="0.014"/>
      </geometry>
      <!-- <geometry>
                    <box size="${foot_length} ${foot_width} ${foot_height}"/>
                </geometry>        -->
    </collision>
    <inertial>
      <mass value="0.03"/>
      <inertia ixx="2.352e-06" ixy="0.0" ixz="0.0" iyy="2.352e-06" iyz="0.0" izz="2.352e-06"/>
    </inertial>
  </link>
  <transmission name="L_hip_tran">
    <type>transmission_interface/SimpleTransmission</type>
    <joint name="L_hip_joint">
      <hardwareInterface>hardware_interface/EffortJointInterface</hardwareInterface>
    </joint>
    <actuator name="L_hip_motor">
      <hardwareInterface>hardware_interface/EffortJointInterface</hardwareInterface>
      <mechanicalReduction>1</mechanicalReduction>
    </actuator>
  </transmission>
  <transmission name="L_hip2_tran">
    <type>transmission_interface/SimpleTransmission</type>
    <joint name="L_hip2_joint">
      <hardwareInterface>hardware_interface/EffortJointInterface</hardwareInterface>
    </joint>
    <actuator name="L_hip2_motor">
      <hardwareInterface>hardware_interface/EffortJointInterface</hardwareInterface>
      <mechanicalReduction>1</mechanicalReduction>
    </actuator>
  </transmission>
  <transmission name="L_thigh_tran">
    <type>transmission_interface/SimpleTransmission</type>
    <joint name="L_thigh_joint">
      <hardwareInterface>hardware_interface/EffortJointInterface</hardwareInterface>
    </joint>
    <actuator name="L_thigh_motor">
      <hardwareInterface>hardware_interface/EffortJointInterface</hardwareInterface>
      <mechanicalReduction>1</mechanicalReduction>
    </actuator>
  </transmission>
  <transmission name="L_calf_tran">
    <type>transmission_interface/SimpleTransmission</type>
    <joint name="L_calf_joint">
      <hardwareInterface>hardware_interface/EffortJointInterface</hardwareInterface>
    </joint>
    <actuator name="L_calf_motor">
      <hardwareInterface>hardware_interface/EffortJointInterface</hardwareInterface>
      <mechanicalReduction>1</mechanicalReduction>
    </actuator>
  </transmission>
  <transmission name="L_toe_tran">
    <type>transmission_interface/SimpleTransmission</type>
    <joint name="L_toe_joint">
      <hardwareInterface>hardware_interface/EffortJointInterface</hardwareInterface>
    </joint>
    <actuator name="L_toe_motor">
      <hardwareInterface>hardware_interface/EffortJointInterface</hardwareInterface>
      <mechanicalReduction>1</mechanicalReduction>
    </actuator>
  </transmission>
  <joint name="R_hip_joint" type="revolute">
    <origin rpy="0 0 0" xyz="0.0 -0.047 -0.1265"/>
    <parent link="trunk"/>
    <child link="R_hip"/>
    <axis xyz="0 0 1"/>
    <dynamics damping="0.1" friction="0.0"/>
    <limit effort="33.5" lower="-0.5235987755982988" upper="0.5235987755982988" velocity="21"/>
  </joint>
  <link name="R_hip">
    <visual>
      <origin rpy="0 0 0" xyz="0 0 0"/>
      <geometry>
        <mesh filename="package://hector_description/meshes/R_hip1.STL" scale="1 1 1"/>
      </geometry>
      <material name="orange"/>
    </visual>
    <collision>
      <origin rpy="0 0 0" xyz="0.015 0.0 -0.002"/>
      <geometry>
        <box size="0.0001 0.0001 0.0001"/>
      </geometry>
    </collision>
    <inertial>
      <origin rpy="0 0 0" xyz="0.025109 -0.002292 -0.024732"/>
      <mass value="0.224"/>
      <inertia ixx="2.104e-06" ixy="0.0" ixz="0.0" iyy="5.354e-06" iyz="0.0" izz="7.416e-06"/>
    </inertial>
  </link>
  <!--this link is only for motor mass&colllision-->
  <joint name="R_hip_trans_joint" type="fixed">
    <origin rpy="0 0 0" xyz="0.079 -0.015 -0.0705"/>
    <parent link="R_hip"/>
    <child link="R_hip_trans"/>
  </joint>
  <link name="R_hip_trans">
    <collision>
      <origin rpy="0 1.5707963267948966 0" xyz="0 0 0"/>
      <geometry>
        <cylinder length="0.04" radius="0.045"/>
      </geometry>
    </collision>
    <inertial>
      <origin rpy="0 0 0" xyz="0 0 0"/>
      <mass value="0.65"/>
      <inertia ixx="0.00043875" ixy="0.0" ixz="0.0" iyy="0.00043875" iyz="0.0" izz="0.000658125"/>
    </inertial>
  </link>
  <joint name="R_hip2_joint" type="revolute">
    <origin rpy="0 0 0" xyz="0.0465 -0.015 -0.0705"/>
    <parent link="R_hip"/>
    <child link="R_hip2"/>
    <axis xyz="1 0 0"/>
    <dynamics damping="0.1" friction="0.0"/>
    <limit effort="33.5" lower="-0.5235987755982988" upper="0.5235987755982988" velocity="21"/>
  </joint>
  <link name="R_hip2">
    <visual>
      <origin rpy="0 0 0" xyz="0 0 0"/>
      <geometry>
        <mesh filename="package://hector_description/meshes/R_hip2.STL" scale="1 1 1"/>
      </geometry>
      <material name="red"/>
    </visual>
    <collision>
      <origin rpy="0 0 0" xyz="-0.1 0 0"/>
      <geometry>
        <box size="1e-05 1e-05 1e-05"/>
      </geometry>
    </collision>
    <inertial>
      <origin rpy="0 0 0" xyz="-0.033217 -0.010231 0"/>
      <mass value="0.095"/>
      <inertia ixx="5.1083e-05" ixy="0.0" ixz="0.0" iyy="1.39825e-05" iyz="0.0" izz="9.3473e-05"/>
    </inertial>
  </link>
  <!--this link is only for collision-->
  <joint name="R_hip2_trans_joint" type="fixed">
    <origin rpy="0 0 0" xyz="-0.06 0.015 0.0"/>
    <parent link="R_hip2"/>
    <child link="R_hip2_trans"/>
  </joint>
  <link name="R_hip2_trans">
    <collision>
      <origin rpy="-1.5707963267948966 0 0" xyz="0 0 0"/>
      <geometry>
        <cylinder length="0.04" radius="0.045"/>
      </geometry>
    </collision>
    <inertial>
      <origin rpy="-1.5707963267948966 0 0" xyz="0 0 0"/>
      <mass value="0.65"/>
      <inertia ixx="0.00043875" ixy="0.0" ixz="0.0" iyy="0.00043875" iyz="0.0" izz="0.000658125"/>
    </inertial>
  </link>
  <joint name="R_thigh_joint" type="revolute">
    <origin rpy="0 0.7853981633974483 0" xyz="-0.06 -0.018 0"/>
    <parent link="R_hip2"/>
    <child link="R_thigh"/>
    <axis xyz="0 1 0"/>
    <joint_properties damping="0.1" friction="0.0"/>
    <!-- <limit effort="${thigh_torque_max}" velocity="${thigh_velocity_max}"/> -->
    <limit effort="33.5" lower="-3.14" upper="3.14" velocity="21"/>
  </joint>
  <link name="R_thigh">
    <visual>
      <origin rpy="0 0 0" xyz="0 0 0"/>
      <geometry>
        <mesh filename="package://hector_description/meshes/R_thigh.STL" scale="1 1 1"/>
      </geometry>
      <material name="white"/>
    </visual>
    <collision>
      <origin rpy="0 0 0" xyz="0.0 -0.0175 -0.09"/>
      <geometry>
        <box size="0.06 0.035 0.18"/>
      </geometry>
    </collision>
    <inertial>
      <origin rpy="0 0 0" xyz="-0.000147 -0.01991 -0.081117"/>
      <mass value="0.642"/>
      <inertia ixx="0.004437615" ixy="0.0" ixz="0.0" iyy="0.004788512" iyz="0.0" izz="0.000661818"/>
    </inertial>
  </link>
  <!--this link is only for collision-->
  <joint name="R_thigh1_trans_joint" type="fixed">
    <origin rpy="0 0 0" xyz="0.0 -0.0625 0.0"/>
    <parent link="R_thigh"/>
    <child link="R_thigh1_trans"/>
  </joint>
  <link name="R_thigh1_trans">
    <collision>
      <origin rpy="-1.5707963267948966 0 0" xyz="0 0 0"/>
      <geometry>
        <cylinder length="0.04" radius="0.045"/>
      </geometry>
    </collision>
    <inertial>
      <origin rpy="-1.5707963267948966 0 0" xyz="0 0 0"/>
      <mass value="0.65"/>
      <inertia ixx="0.00043875" ixy="0.0" ixz="0.0" iyy="0.00043875" iyz="0.0" izz="0.000658125"/>
    </inertial>
  </link>
  <!--this link is only for collision-->
  <joint name="R_thigh2_trans_joint" type="fixed">
    <origin rpy="0 0 0" xyz="0.0 0.0225 -0.097"/>
    <parent link="R_thigh"/>
    <child link="R_thigh2_trans"/>
  </joint>
  <link name="R_thigh2_trans">
    <collision>
      <origin rpy="-1.5707963267948966 0 0" xyz="0 0 0"/>
      <geometry>
        <cylinder length="0.04" radius="0.045"/>
      </geometry>
    </collision>
    <inertial>
      <origin rpy="-1.5707963267948966 0 0" xyz="0 0 0"/>
      <mass value="0.65"/>
      <inertia ixx="0.00043875" ixy="0.0" ixz="0.0" iyy="0.00043875" iyz="0.0" izz="0.000658125"/>
    </inertial>
  </link>
  <joint name="R_calf_joint" type="revolute">
    <origin rpy="0 -1.5707963267948966 0" xyz="0.0 0 -0.22"/>
    <parent link="R_thigh"/>
    <child link="R_calf"/>
    <axis xyz="0 1 0"/>
    <joint_properties damping="0.1" friction="0.0"/>
    <limit effort="33.5" lower="-3.14" upper="3.14" velocity="21"/>
  </joint>
  <link name="R_calf">
    <visual>
      <origin rpy="0 0 0" xyz="0 0 0"/>
      <geometry>
        <mesh filename="package://hector_description/meshes/R_calf.STL" scale="1 1 1"/>
      </geometry>
      <material name="orange"/>
    </visual>
    <collision>
      <origin rpy="0 0 0" xyz="0.0 0.0 -0.11"/>
      <geometry>
        <cylinder length="0.2" radius="0.015"/>
      </geometry>
    </collision>
    <inertial>
      <origin rpy="0 0 0" xyz="0.0 -0.020417 -0.1141"/>
      <mass value="0.303"/>
      <inertia ixx="0.001911" ixy="0.0" ixz="0.0" iyy="0.00191038" iyz="0.0" izz="6.8352e-05"/>
    </inertial>
  </link>
  <joint name="R_toe_joint" type="revolute">
    <origin rpy="0 0.7853981633974483 0" xyz="0.0 0.0 -0.22"/>
    <parent link="R_calf"/>
    <child link="R_toe"/>
    <axis xyz="0 1 0"/>
    <joint_properties damping="0.1" friction="0.0"/>
    <limit effort="33.5" lower="-1.4" upper="1.4" velocity="21"/>
  </joint>
  <link name="R_toe">
    <visual>
      <origin rpy="0 0 0" xyz="0 0 0"/>
      <geometry>
        <mesh filename="package://hector_description/meshes/R_foot.STL" scale="1 1 1"/>
      </geometry>
      <material name="red"/>
    </visual>
    <collision>
      <origin rpy="0 0 0" xyz="0.01 -0.0194 -0.02"/>
      <geometry>
        <box size="0.15 0.02 0.04"/>
      </geometry>
    </collision>
    <inertial>
      <origin rpy="0 0 0" xyz="0.010569 -0.017949 -0.017118"/>
      <mass value="0.214"/>
      <inertia ixx="5.7298e-05" ixy="0.0" ixz="0.0" iyy="0.000290752" iyz="0.0" izz="0.000249491"/>
    </inertial>
  </link>
  <joint name="R_foot_fixed_1" type="revolute">
    <origin rpy="0 0 0" xyz="0.0 -0.0 -0.04"/>
    <parent link="R_toe"/>
    <child link="R_foot_link_1"/>
    <!-- just for generate jacobian -->
    <axis xyz="0 1 0"/>
    <joint_properties damping="0.1" friction="0.0"/>
    <limit effort="33.5" lower="-1.4" upper="1.4" velocity="21"/>
  </joint>
  <link name="R_foot_link_1">
    <visual>
      <origin rpy="0 0 0" xyz="0.0 -0.0 -0.02"/>
      <geometry>
        <sphere radius="0.004"/>
      </geometry>
      <!-- <geometry>
                    <box size="${foot_length} ${foot_width} ${foot_height}"/>
                </geometry>  -->
      <material name="blue"/>
    </visual>
    <collision>
      <origin rpy="0 0 0" xyz="0.0 -0.0 -0.02"/>
      <geometry>
        <sphere radius="0.014"/>
      </geometry>
      <!-- <geometry>
                    <box size="${foot_length} ${foot_width} ${foot_height}"/>
                </geometry>        -->
    </collision>
    <inertial>
      <mass value="0.03"/>
      <inertia ixx="2.352e-06" ixy="0.0" ixz="0.0" iyy="2.352e-06" iyz="0.0" izz="2.352e-06"/>
    </inertial>
  </link>
  <transmission name="R_hip_tran">
    <type>transmission_interface/SimpleTransmission</type>
    <joint name="R_hip_joint">
      <hardwareInterface>hardware_interface/EffortJointInterface</hardwareInterface>
    </joint>
    <actuator name="R_hip_motor">
      <hardwareInterface>hardware_interface/EffortJointInterface</hardwareInterface>
      <mechanicalReduction>1</mechanicalReduction>
    </actuator>
  </transmission>
  <transmission name="R_hip2_tran">
    <type>transmission_interface/SimpleTransmission</type>
    <joint name="R_hip2_joint">
      <hardwareInterface>hardware_interface/EffortJointInterface</hardwareInterface>
    </joint>
    <actuator name="R_hip2_motor">
      <hardwareInterface>hardware_interface/EffortJointInterface</hardwareInterface>
      <mechanicalReduction>1</mechanicalReduction>
    </actuator>
  </transmission>
  <transmission name="R_thigh_tran">
    <type>transmission_interface/SimpleTransmission</type>
    <joint name="R_thigh_joint">
      <hardwareInterface>hardware_interface/EffortJointInterface</hardwareInterface>
    </joint>
    <actuator name="R_thigh_motor">
      <hardwareInterface>hardware_interface/EffortJointInterface</hardwareInterface>
      <mechanicalReduction>1</mechanicalReduction>
    </actuator>
  </transmission>
  <transmission name="R_calf_tran">
    <type>transmission_interface/SimpleTransmission</type>
    <joint name="R_calf_joint">
      <hardwareInterface>hardware_interface/EffortJointInterface</hardwareInterface>
    </joint>
    <actuator name="R_calf_motor">
      <hardwareInterface>hardware_interface/EffortJointInterface</hardwareInterface>
      <mechanicalReduction>1</mechanicalReduction>
    </actuator>
  </transmission>
  <transmission name="R_toe_tran">
    <type>transmission_interface/SimpleTransmission</type>
    <joint name="R_toe_joint">
      <hardwareInterface>hardware_interface/EffortJointInterface</hardwareInterface>
    </joint>
    <actuator name="R_toe_motor">
      <hardwareInterface>hardware_interface/EffortJointInterface</hardwareInterface>
      <mechanicalReduction>1</mechanicalReduction>
    </actuator>
  </transmission>
  <joint name="L_twist_joint" type="revolute">
    <origin rpy="0 0 0" xyz="0.0 -0.047 0.1725"/>
    <parent link="trunk"/>
    <child link="L_twist"/>
    <axis xyz="0 0 1"/>
    <dynamics damping="0.1" friction="0.0"/>
    <limit effort="33.5" lower="-1.4" upper="1.4" velocity="21"/>
  </joint>
  <link name="L_twist">
    <visual>
      <origin rpy="0 -1.5707963267948966 0" xyz="0 0 0"/>
      <geometry>
        <mesh filename="package://hector_description/meshes/hip_a1.dae" scale="1 1 1"/>
      </geometry>
      <material name="orange"/>
    </visual>
    <collision>
      <origin rpy="1.5707963267948966 0 0" xyz="0 -0.021 0"/>
      <geometry>
        <cylinder length="0.08" radius="0.041"/>
      </geometry>
    </collision>
    <inertial>
      <origin rpy="0 0 0" xyz="-0.001568 -0.008134 0.000864"/>
      <mass value="0.1096"/>
      <inertia ixx="0.000822113" ixy="-4.982e-06" ixz="-3.672e-05" iyy="0.000983196" iyz="2.811e-06" izz="0.000864753"/>
    </inertial>
    <!-- <inertial>
            <origin rpy="0 0 0" xyz="0.025109 -0.002292 -0.024732"/>
            <mass value="0.1"/>
            <inertia ixx="2.104e-02" ixy="0.0" ixz="0.0" iyy="5.354e-02" iyz="0.0" izz="7.416e-02"/>
            </inertial> -->
  </link>
  <joint name="L_shoulder_joint" type="revolute">
    <origin rpy="0 0 0" xyz="0.0 -0.0723 0.0"/>
    <parent link="L_twist"/>
    <child link="L_shoulder"/>
    <axis xyz="0 1 0"/>
    <dynamics damping="0.1" friction="0.0"/>
    <limit effort="33.5" lower="-1.4" upper="1.4" velocity="21"/>
  </joint>
  <link name="L_shoulder">
    <visual>
      <origin rpy="0 0 0" xyz="0 0 0"/>
      <geometry>
        <mesh filename="package://hector_description/meshes/thigh_mirror_a1.dae" scale="1 1 1"/>
      </geometry>
      <material name="orange"/>
    </visual>
    <collision>
      <origin rpy="0 1.5707963267948966 0" xyz="0 0 -0.125"/>
      <geometry>
        <box size="0.25 0.034 0.043"/>
      </geometry>
    </collision>
    <inertial>
      <origin rpy="0 0 0" xyz="-0.000482 0.02001 -0.031996"/>
      <mass value="0.1528"/>
      <inertia ixx="0.00991611" ixy="1.0388e-05" ixz="0.000250428" iyy="0.009280083" iyz="-8.511e-05" izz="0.00178256"/>
    </inertial>
  </link>
  <joint name="L_elbow_joint" type="revolute">
    <origin rpy="0 -1.5 0" xyz="0.0 0.0 -0.205"/>
    <parent link="L_shoulder"/>
    <child link="L_elbow"/>
    <axis xyz="0 1 0"/>
    <dynamics damping="0.1" friction="0.0"/>
    <limit effort="33.5" lower="-1.4" upper="1.4" velocity="21"/>
  </joint>
  <link name="L_elbow">
    <visual>
      <origin rpy="0 0 0" xyz="0 0 0"/>
      <geometry>
        <mesh filename="package://hector_description/meshes/calf_a1.dae" scale="1 1 1"/>
      </geometry>
      <material name="orange"/>
    </visual>
    <collision>
      <origin rpy="0 1.5707963267948966 0" xyz="0 0 -0.125"/>
      <geometry>
        <box size="0.25 0.016 0.016"/>
      </geometry>
    </collision>
    <inertial>
      <origin rpy="0 0 0" xyz="-0.002196 -0.000381 -0.12338"/>
      <mass value="0.0241"/>
      <inertia ixx="0.006181961" ixy="2.37e-07" ixz="-2.985e-06" iyy="0.006196546" iyz="5.138e-06" izz="3.4774e-05"/>
    </inertial>
  </link>
  <!--Left arm  -->
  <transmission name="L_twist_tran">
    <type>transmission_interface/SimpleTransmission</type>
    <joint name="L_twist_joint">
      <hardwareInterface>hardware_interface/EffortJointInterface</hardwareInterface>
    </joint>
    <actuator name="L_twist_motor">
      <hardwareInterface>hardware_interface/EffortJointInterface</hardwareInterface>
      <mechanicalReduction>1</mechanicalReduction>
    </actuator>
  </transmission>
  <transmission name="L_shoulder_tran">
    <type>transmission_interface/SimpleTransmission</type>
    <joint name="L_shoulder_joint">
      <hardwareInterface>hardware_interface/EffortJointInterface</hardwareInterface>
    </joint>
    <actuator name="L_shoulder_motor">
      <hardwareInterface>hardware_interface/EffortJointInterface</hardwareInterface>
      <mechanicalReduction>1</mechanicalReduction>
    </actuator>
  </transmission>
  <transmission name="L_elbow_tran">
    <type>transmission_interface/SimpleTransmission</type>
    <joint name="L_elbow_joint">
      <hardwareInterface>hardware_interface/EffortJointInterface</hardwareInterface>
    </joint>
    <actuator name="L_elbow_motor">
      <hardwareInterface>hardware_interface/EffortJointInterface</hardwareInterface>
      <mechanicalReduction>1</mechanicalReduction>
    </actuator>
  </transmission>
  <joint name="R_twist_joint" type="revolute">
    <origin rpy="0 0 0" xyz="0.0 0.047 0.1725"/>
    <parent link="trunk"/>
    <child link="R_twist"/>
    <axis xyz="0 0 1"/>
    <dynamics damping="0.1" friction="0.0"/>
    <limit effort="33.5" lower="-1.4" upper="1.4" velocity="21"/>
  </joint>
  <link name="R_twist">
    <visual>
      <origin rpy="0 -1.5707963267948966 0" xyz="0 0 0"/>
      <geometry>
        <mesh filename="package://hector_description/meshes/hip_a1.dae" scale="1 1 1"/>
      </geometry>
      <material name="orange"/>
    </visual>
    <collision>
      <origin rpy="1.5707963267948966 0 0" xyz="0 0.021 0"/>
      <geometry>
        <cylinder length="0.08" radius="0.041"/>
      </geometry>
    </collision>
    <inertial>
      <origin rpy="0 0 0" xyz="-0.001568 0.008134 0.000864"/>
      <mass value="0.1096"/>
      <inertia ixx="0.000822113" ixy="4.982e-06" ixz="-3.672e-05" iyy="0.000983196" iyz="-2.811e-06" izz="0.000864753"/>
    </inertial>
    <!-- <inertial>
            <origin rpy="0 0 0" xyz="0.025109 -0.002292 -0.024732"/>
            <mass value="0.1"/>
            <inertia ixx="2.104e-02" ixy="0.0" ixz="0.0" iyy="5.354e-02" iyz="0.0" izz="7.416e-02"/>
            </inertial> -->
  </link>
  <joint name="R_shoulder_joint" type="revolute">
    <origin rpy="0 0 0" xyz="0.0 0.0723 0.0"/>
    <parent link="R_twist"/>
    <child link="R_shoulder"/>
    <axis xyz="0 1 0"/>
    <dynamics damping="0.1" friction="0.0"/>
    <limit effort="33.5" lower="-1.4" upper="1.4" velocity="21"/>
  </joint>
  <link name="R_shoulder">
    <visual>
      <origin rpy="0 0 0" xyz="0 0 0"/>
      <geometry>
        <mesh filename="package://hector_description/meshes/thigh_a1.dae" scale="1 1 1"/>
      </geometry>
      <material name="orange"/>
    </visual>
    <collision>
      <origin rpy="0 1.5707963267948966 0" xyz="0 0 -0.125"/>
      <geometry>
        <box size="0.25 0.034 0.043"/>
      </geometry>
    </collision>
    <inertial>
      <origin rpy="0 0 0" xyz="-0.000482 -0.02001 -0.031996"/>
      <mass value="0.1528"/>
      <inertia ixx="0.00991611" ixy="-1.0388e-05" ixz="0.000250428" iyy="0.009280083" iyz="8.511e-05" izz="0.00178256"/>
    </inertial>
  </link>
  <joint name="R_elbow_joint" type="revolute">
    <origin rpy="0 -1.5 0" xyz="0.0 0.0 -0.205"/>
    <parent link="R_shoulder"/>
    <child link="R_elbow"/>
    <axis xyz="0 1 0"/>
    <dynamics damping="0.1" friction="0.0"/>
    <limit effort="33.5" lower="-1.4" upper="1.4" velocity="21"/>
  </joint>
  <link name="R_elbow">
    <visual>
      <origin rpy="0 0 0" xyz="0 0 0"/>
      <geometry>
        <mesh filename="package://hector_description/meshes/calf_a1.dae" scale="1 1 1"/>
      </geometry>
      <material name="orange"/>
    </visual>
    <collision>
      <origin rpy="0 1.5707963267948966 0" xyz="0 0 -0.125"/>
      <geometry>
        <box size="0.25 0.016 0.016"/>
      </geometry>
    </collision>
    <inertial>
      <origin rpy="0 0 0" xyz="-0.002196 -0.000381 -0.12338"/>
      <mass value="0.0241"/>
      <inertia ixx="0.006181961" ixy="2.37e-07" ixz="-2.985e-06" iyy="0.006196546" iyz="5.138e-06" izz="3.4774e-05"/>
    </inertial>
  </link>
  <!--Left arm  -->
  <transmission name="R_twist_tran">
    <type>transmission_interface/SimpleTransmission</type>
    <joint name="R_twist_joint">
      <hardwareInterface>hardware_interface/EffortJointInterface</hardwareInterface>
    </joint>
    <actuator name="R_twist_motor">
      <hardwareInterface>hardware_interface/EffortJointInterface</hardwareInterface>
      <mechanicalReduction>1</mechanicalReduction>
    </actuator>
  </transmission>
  <transmission name="R_shoulder_tran">
    <type>transmission_interface/SimpleTransmission</type>
    <joint name="R_shoulder_joint">
      <hardwareInterface>hardware_interface/EffortJointInterface</hardwareInterface>
    </joint>
    <actuator name="R_shoulder_motor">
      <hardwareInterface>hardware_interface/EffortJointInterface</hardwareInterface>
      <mechanicalReduction>1</mechanicalReduction>
    </actuator>
  </transmission>
  <transmission name="R_elbow_tran">
    <type>transmission_interface/SimpleTransmission</type>
    <joint name="R_elbow_joint">
      <hardwareInterface>hardware_interface/EffortJointInterface</hardwareInterface>
    </joint>
    <actuator name="R_elbow_motor">
      <hardwareInterface>hardware_interface/EffortJointInterface</hardwareInterface>
      <mechanicalReduction>1</mechanicalReduction>
    </actuator>
  </transmission>
</robot>
